[2022-11-01 20:40:14,010] {taskinstance.py:1159} INFO - Dependencies all met for <TaskInstance: xetra_DAG.run_xetra_etl scheduled__2022-11-01T20:26:00+00:00 [queued]>
[2022-11-01 20:40:14,125] {taskinstance.py:1159} INFO - Dependencies all met for <TaskInstance: xetra_DAG.run_xetra_etl scheduled__2022-11-01T20:26:00+00:00 [queued]>
[2022-11-01 20:40:14,136] {taskinstance.py:1356} INFO - 
--------------------------------------------------------------------------------
[2022-11-01 20:40:14,146] {taskinstance.py:1357} INFO - Starting attempt 2 of 2
[2022-11-01 20:40:14,152] {taskinstance.py:1358} INFO - 
--------------------------------------------------------------------------------
[2022-11-01 20:40:14,305] {taskinstance.py:1377} INFO - Executing <Task(PythonOperator): run_xetra_etl> on 2022-11-01 20:26:00+00:00
[2022-11-01 20:40:14,338] {standard_task_runner.py:52} INFO - Started process 9386 to run task
[2022-11-01 20:40:14,385] {standard_task_runner.py:79} INFO - Running: ['***', 'tasks', 'run', 'xetra_DAG', 'run_xetra_etl', 'scheduled__2022-11-01T20:26:00+00:00', '--job-id', '71', '--raw', '--subdir', 'DAGS_FOLDER/xetra_DAG.py', '--cfg-path', '/tmp/tmpal2emelm', '--error-file', '/tmp/tmp632bf10d']
[2022-11-01 20:40:14,399] {standard_task_runner.py:80} INFO - Job 71: Subtask run_xetra_etl
[2022-11-01 20:40:14,836] {task_command.py:369} INFO - Running <TaskInstance: xetra_DAG.run_xetra_etl scheduled__2022-11-01T20:26:00+00:00 [running]> on host 029aeb09b6d8
[2022-11-01 20:40:15,360] {taskinstance.py:1571} INFO - Exporting the following env vars:
AIRFLOW_CTX_DAG_EMAIL=***@example.com
AIRFLOW_CTX_DAG_OWNER=***
AIRFLOW_CTX_DAG_ID=xetra_DAG
AIRFLOW_CTX_TASK_ID=run_xetra_etl
AIRFLOW_CTX_EXECUTION_DATE=2022-11-01T20:26:00+00:00
AIRFLOW_CTX_TRY_NUMBER=2
AIRFLOW_CTX_DAG_RUN_ID=scheduled__2022-11-01T20:26:00+00:00
[2022-11-01 20:40:15,364] {logging_mixin.py:115} INFO - /opt\meta_file.csv
[2022-11-01 20:40:15,373] {taskinstance.py:1889} ERROR - Task failed with exception
Traceback (most recent call last):
  File "/home/airflow/.local/lib/python3.7/site-packages/airflow/operators/python.py", line 171, in execute
    return_value = self.execute_callable()
  File "/home/airflow/.local/lib/python3.7/site-packages/airflow/operators/python.py", line 189, in execute_callable
    return self.python_callable(*self.op_args, **self.op_kwargs)
  File "/opt/airflow/dags/xetra_etl.py", line 80, in run_etl
    date_to_process, previous_date = return_required_dates(META_FILE_PATH, src_date_format, INITIAL_DATE, today)
  File "/opt/airflow/dags/xetra_etl.py", line 13, in return_required_dates
    df_meta_file = pd.read_csv(meta_file_path)
  File "/home/airflow/.local/lib/python3.7/site-packages/pandas/util/_decorators.py", line 311, in wrapper
    return func(*args, **kwargs)
  File "/home/airflow/.local/lib/python3.7/site-packages/pandas/io/parsers/readers.py", line 586, in read_csv
    return _read(filepath_or_buffer, kwds)
  File "/home/airflow/.local/lib/python3.7/site-packages/pandas/io/parsers/readers.py", line 482, in _read
    parser = TextFileReader(filepath_or_buffer, **kwds)
  File "/home/airflow/.local/lib/python3.7/site-packages/pandas/io/parsers/readers.py", line 811, in __init__
    self._engine = self._make_engine(self.engine)
  File "/home/airflow/.local/lib/python3.7/site-packages/pandas/io/parsers/readers.py", line 1040, in _make_engine
    return mapping[engine](self.f, **self.options)  # type: ignore[call-arg]
  File "/home/airflow/.local/lib/python3.7/site-packages/pandas/io/parsers/c_parser_wrapper.py", line 51, in __init__
    self._open_handles(src, kwds)
  File "/home/airflow/.local/lib/python3.7/site-packages/pandas/io/parsers/base_parser.py", line 229, in _open_handles
    errors=kwds.get("encoding_errors", "strict"),
  File "/home/airflow/.local/lib/python3.7/site-packages/pandas/io/common.py", line 707, in get_handle
    newline="",
FileNotFoundError: [Errno 2] No such file or directory: '/opt\\meta_file.csv'
[2022-11-01 20:40:15,460] {taskinstance.py:1400} INFO - Marking task as FAILED. dag_id=xetra_DAG, task_id=run_xetra_etl, execution_date=20221101T202600, start_date=20221101T204014, end_date=20221101T204015
[2022-11-01 20:40:15,535] {standard_task_runner.py:97} ERROR - Failed to execute job 71 for task run_xetra_etl ([Errno 2] No such file or directory: '/opt\\meta_file.csv'; 9386)
[2022-11-01 20:40:15,602] {local_task_job.py:156} INFO - Task exited with return code 1
[2022-11-01 20:40:15,821] {local_task_job.py:273} INFO - 0 downstream tasks scheduled from follow-on schedule check
