[2022-11-02 13:51:45,003] {taskinstance.py:1159} INFO - Dependencies all met for <TaskInstance: xetra_DAG.run_xetra_etl manual__2022-11-02T13:49:45.995384+00:00 [queued]>
[2022-11-02 13:51:45,047] {taskinstance.py:1159} INFO - Dependencies all met for <TaskInstance: xetra_DAG.run_xetra_etl manual__2022-11-02T13:49:45.995384+00:00 [queued]>
[2022-11-02 13:51:45,056] {taskinstance.py:1356} INFO - 
--------------------------------------------------------------------------------
[2022-11-02 13:51:45,059] {taskinstance.py:1357} INFO - Starting attempt 2 of 2
[2022-11-02 13:51:45,061] {taskinstance.py:1358} INFO - 
--------------------------------------------------------------------------------
[2022-11-02 13:51:46,247] {taskinstance.py:1377} INFO - Executing <Task(PythonOperator): run_xetra_etl> on 2022-11-02 13:49:45.995384+00:00
[2022-11-02 13:51:46,258] {standard_task_runner.py:52} INFO - Started process 152 to run task
[2022-11-02 13:51:46,267] {standard_task_runner.py:79} INFO - Running: ['***', 'tasks', 'run', 'xetra_DAG', 'run_xetra_etl', 'manual__2022-11-02T13:49:45.995384+00:00', '--job-id', '127', '--raw', '--subdir', 'DAGS_FOLDER/xetra_DAG.py', '--cfg-path', '/tmp/tmpiu9bm37n', '--error-file', '/tmp/tmphbjjecrq']
[2022-11-02 13:51:46,272] {standard_task_runner.py:80} INFO - Job 127: Subtask run_xetra_etl
[2022-11-02 13:51:46,565] {task_command.py:369} INFO - Running <TaskInstance: xetra_DAG.run_xetra_etl manual__2022-11-02T13:49:45.995384+00:00 [running]> on host 4d817fca145d
[2022-11-02 13:52:02,860] {taskinstance.py:1571} INFO - Exporting the following env vars:
AIRFLOW_CTX_DAG_EMAIL=***@example.com
AIRFLOW_CTX_DAG_OWNER=***
AIRFLOW_CTX_DAG_ID=xetra_DAG
AIRFLOW_CTX_TASK_ID=run_xetra_etl
AIRFLOW_CTX_EXECUTION_DATE=2022-11-02T13:49:45.995384+00:00
AIRFLOW_CTX_TRY_NUMBER=2
AIRFLOW_CTX_DAG_RUN_ID=manual__2022-11-02T13:49:45.995384+00:00
[2022-11-02 13:52:02,863] {logging_mixin.py:115} INFO - curent path is /opt/***
[2022-11-02 13:52:02,864] {logging_mixin.py:115} INFO - /opt/meta_file.csv
[2022-11-02 13:52:02,867] {taskinstance.py:1889} ERROR - Task failed with exception
Traceback (most recent call last):
  File "/home/airflow/.local/lib/python3.7/site-packages/airflow/operators/python.py", line 171, in execute
    return_value = self.execute_callable()
  File "/home/airflow/.local/lib/python3.7/site-packages/airflow/operators/python.py", line 189, in execute_callable
    return self.python_callable(*self.op_args, **self.op_kwargs)
  File "/opt/airflow/dags/xetra_etl.py", line 81, in run_etl
    date_to_process, previous_date = return_required_dates(META_FILE_PATH, src_date_format, INITIAL_DATE, today)
  File "/opt/airflow/dags/xetra_etl.py", line 13, in return_required_dates
    df_meta_file = pd.read_csv(meta_file_path)
  File "/home/airflow/.local/lib/python3.7/site-packages/pandas/util/_decorators.py", line 311, in wrapper
    return func(*args, **kwargs)
  File "/home/airflow/.local/lib/python3.7/site-packages/pandas/io/parsers/readers.py", line 586, in read_csv
    return _read(filepath_or_buffer, kwds)
  File "/home/airflow/.local/lib/python3.7/site-packages/pandas/io/parsers/readers.py", line 482, in _read
    parser = TextFileReader(filepath_or_buffer, **kwds)
  File "/home/airflow/.local/lib/python3.7/site-packages/pandas/io/parsers/readers.py", line 811, in __init__
    self._engine = self._make_engine(self.engine)
  File "/home/airflow/.local/lib/python3.7/site-packages/pandas/io/parsers/readers.py", line 1040, in _make_engine
    return mapping[engine](self.f, **self.options)  # type: ignore[call-arg]
  File "/home/airflow/.local/lib/python3.7/site-packages/pandas/io/parsers/c_parser_wrapper.py", line 51, in __init__
    self._open_handles(src, kwds)
  File "/home/airflow/.local/lib/python3.7/site-packages/pandas/io/parsers/base_parser.py", line 229, in _open_handles
    errors=kwds.get("encoding_errors", "strict"),
  File "/home/airflow/.local/lib/python3.7/site-packages/pandas/io/common.py", line 707, in get_handle
    newline="",
FileNotFoundError: [Errno 2] No such file or directory: '/opt/meta_file.csv'
[2022-11-02 13:52:02,932] {taskinstance.py:1400} INFO - Marking task as FAILED. dag_id=xetra_DAG, task_id=run_xetra_etl, execution_date=20221102T134945, start_date=20221102T135145, end_date=20221102T135202
[2022-11-02 13:52:03,411] {standard_task_runner.py:97} ERROR - Failed to execute job 127 for task run_xetra_etl ([Errno 2] No such file or directory: '/opt/meta_file.csv'; 152)
[2022-11-02 13:52:03,478] {local_task_job.py:156} INFO - Task exited with return code 1
[2022-11-02 13:52:03,549] {local_task_job.py:273} INFO - 0 downstream tasks scheduled from follow-on schedule check
