[2022-11-02 13:55:07,174] {taskinstance.py:1159} INFO - Dependencies all met for <TaskInstance: xetra_DAG.run_xetra_etl manual__2022-11-02T13:54:01.885191+00:00 [queued]>
[2022-11-02 13:55:07,196] {taskinstance.py:1159} INFO - Dependencies all met for <TaskInstance: xetra_DAG.run_xetra_etl manual__2022-11-02T13:54:01.885191+00:00 [queued]>
[2022-11-02 13:55:07,197] {taskinstance.py:1356} INFO - 
--------------------------------------------------------------------------------
[2022-11-02 13:55:07,197] {taskinstance.py:1357} INFO - Starting attempt 2 of 2
[2022-11-02 13:55:07,199] {taskinstance.py:1358} INFO - 
--------------------------------------------------------------------------------
[2022-11-02 13:55:07,245] {taskinstance.py:1377} INFO - Executing <Task(PythonOperator): run_xetra_etl> on 2022-11-02 13:54:01.885191+00:00
[2022-11-02 13:55:07,289] {standard_task_runner.py:52} INFO - Started process 228 to run task
[2022-11-02 13:55:07,303] {standard_task_runner.py:79} INFO - Running: ['***', 'tasks', 'run', 'xetra_DAG', 'run_xetra_etl', 'manual__2022-11-02T13:54:01.885191+00:00', '--job-id', '129', '--raw', '--subdir', 'DAGS_FOLDER/xetra_DAG.py', '--cfg-path', '/tmp/tmpl7wt0iqq', '--error-file', '/tmp/tmpxi6o22s5']
[2022-11-02 13:55:07,308] {standard_task_runner.py:80} INFO - Job 129: Subtask run_xetra_etl
[2022-11-02 13:55:08,029] {task_command.py:369} INFO - Running <TaskInstance: xetra_DAG.run_xetra_etl manual__2022-11-02T13:54:01.885191+00:00 [running]> on host 4d817fca145d
[2022-11-02 13:55:08,235] {taskinstance.py:1571} INFO - Exporting the following env vars:
AIRFLOW_CTX_DAG_EMAIL=***@example.com
AIRFLOW_CTX_DAG_OWNER=***
AIRFLOW_CTX_DAG_ID=xetra_DAG
AIRFLOW_CTX_TASK_ID=run_xetra_etl
AIRFLOW_CTX_EXECUTION_DATE=2022-11-02T13:54:01.885191+00:00
AIRFLOW_CTX_TRY_NUMBER=2
AIRFLOW_CTX_DAG_RUN_ID=manual__2022-11-02T13:54:01.885191+00:00
[2022-11-02 13:55:08,238] {logging_mixin.py:115} INFO - /opt/***/meta_file.csv
[2022-11-02 13:55:08,242] {taskinstance.py:1889} ERROR - Task failed with exception
Traceback (most recent call last):
  File "/home/airflow/.local/lib/python3.7/site-packages/airflow/operators/python.py", line 171, in execute
    return_value = self.execute_callable()
  File "/home/airflow/.local/lib/python3.7/site-packages/airflow/operators/python.py", line 189, in execute_callable
    return self.python_callable(*self.op_args, **self.op_kwargs)
  File "/opt/airflow/dags/xetra_etl.py", line 81, in run_etl
    date_to_process, previous_date = return_required_dates(META_FILE_PATH, src_date_format, INITIAL_DATE, today)
  File "/opt/airflow/dags/xetra_etl.py", line 13, in return_required_dates
    df_meta_file = pd.read_csv(meta_file_path)
  File "/home/airflow/.local/lib/python3.7/site-packages/pandas/util/_decorators.py", line 311, in wrapper
    return func(*args, **kwargs)
  File "/home/airflow/.local/lib/python3.7/site-packages/pandas/io/parsers/readers.py", line 586, in read_csv
    return _read(filepath_or_buffer, kwds)
  File "/home/airflow/.local/lib/python3.7/site-packages/pandas/io/parsers/readers.py", line 482, in _read
    parser = TextFileReader(filepath_or_buffer, **kwds)
  File "/home/airflow/.local/lib/python3.7/site-packages/pandas/io/parsers/readers.py", line 811, in __init__
    self._engine = self._make_engine(self.engine)
  File "/home/airflow/.local/lib/python3.7/site-packages/pandas/io/parsers/readers.py", line 1040, in _make_engine
    return mapping[engine](self.f, **self.options)  # type: ignore[call-arg]
  File "/home/airflow/.local/lib/python3.7/site-packages/pandas/io/parsers/c_parser_wrapper.py", line 51, in __init__
    self._open_handles(src, kwds)
  File "/home/airflow/.local/lib/python3.7/site-packages/pandas/io/parsers/base_parser.py", line 229, in _open_handles
    errors=kwds.get("encoding_errors", "strict"),
  File "/home/airflow/.local/lib/python3.7/site-packages/pandas/io/common.py", line 707, in get_handle
    newline="",
IsADirectoryError: [Errno 21] Is a directory: '/opt/airflow/meta_file.csv'
[2022-11-02 13:55:08,275] {taskinstance.py:1400} INFO - Marking task as FAILED. dag_id=xetra_DAG, task_id=run_xetra_etl, execution_date=20221102T135401, start_date=20221102T135507, end_date=20221102T135508
[2022-11-02 13:55:08,309] {standard_task_runner.py:97} ERROR - Failed to execute job 129 for task run_xetra_etl ([Errno 21] Is a directory: '/opt/airflow/meta_file.csv'; 228)
[2022-11-02 13:55:08,363] {local_task_job.py:156} INFO - Task exited with return code 1
[2022-11-02 13:55:08,684] {local_task_job.py:273} INFO - 0 downstream tasks scheduled from follow-on schedule check
