[2022-11-13 13:11:15,771] {taskinstance.py:1153} INFO - Dependencies not met for <TaskInstance: xetra_DAG.run_xetra_etl scheduled__2022-11-09T15:00:00+00:00 [up_for_retry]>, dependency 'Not In Retry Period' FAILED: Task is not ready for retry yet but will be retried automatically. Current date is 2022-11-13T13:11:15.771769+00:00 and task will be retried at 2022-11-13T13:12:02.047700+00:00.
[2022-11-13 13:11:15,802] {local_task_job.py:101} INFO - Task is not able to be run
