[2022-11-01 18:50:08,276] {taskinstance.py:1159} INFO - Dependencies all met for <TaskInstance: xetra_DAG.run_xetra_etl manual__2022-11-01T18:48:36.703406+00:00 [queued]>
[2022-11-01 18:50:08,301] {taskinstance.py:1159} INFO - Dependencies all met for <TaskInstance: xetra_DAG.run_xetra_etl manual__2022-11-01T18:48:36.703406+00:00 [queued]>
[2022-11-01 18:50:08,302] {taskinstance.py:1356} INFO - 
--------------------------------------------------------------------------------
[2022-11-01 18:50:08,303] {taskinstance.py:1357} INFO - Starting attempt 2 of 2
[2022-11-01 18:50:08,304] {taskinstance.py:1358} INFO - 
--------------------------------------------------------------------------------
[2022-11-01 18:50:08,346] {taskinstance.py:1377} INFO - Executing <Task(PythonOperator): run_xetra_etl> on 2022-11-01 18:48:36.703406+00:00
[2022-11-01 18:50:08,353] {standard_task_runner.py:52} INFO - Started process 4946 to run task
[2022-11-01 18:50:08,360] {standard_task_runner.py:79} INFO - Running: ['***', 'tasks', 'run', 'xetra_DAG', 'run_xetra_etl', 'manual__2022-11-01T18:48:36.703406+00:00', '--job-id', '4', '--raw', '--subdir', 'DAGS_FOLDER/xetra_DAG.py', '--cfg-path', '/tmp/tmp5_x8lrkv', '--error-file', '/tmp/tmpxzge98v4']
[2022-11-01 18:50:08,361] {standard_task_runner.py:80} INFO - Job 4: Subtask run_xetra_etl
[2022-11-01 18:50:08,485] {task_command.py:369} INFO - Running <TaskInstance: xetra_DAG.run_xetra_etl manual__2022-11-01T18:48:36.703406+00:00 [running]> on host 029aeb09b6d8
[2022-11-01 18:50:08,774] {taskinstance.py:1571} INFO - Exporting the following env vars:
AIRFLOW_CTX_DAG_EMAIL=***@example.com
AIRFLOW_CTX_DAG_OWNER=***
AIRFLOW_CTX_DAG_ID=xetra_DAG
AIRFLOW_CTX_TASK_ID=run_xetra_etl
AIRFLOW_CTX_EXECUTION_DATE=2022-11-01T18:48:36.703406+00:00
AIRFLOW_CTX_TRY_NUMBER=2
AIRFLOW_CTX_DAG_RUN_ID=manual__2022-11-01T18:48:36.703406+00:00
[2022-11-01 18:50:09,381] {taskinstance.py:1889} ERROR - Task failed with exception
Traceback (most recent call last):
  File "/home/airflow/.local/lib/python3.7/site-packages/airflow/operators/python.py", line 171, in execute
    return_value = self.execute_callable()
  File "/home/airflow/.local/lib/python3.7/site-packages/airflow/operators/python.py", line 189, in execute_callable
    return self.python_callable(*self.op_args, **self.op_kwargs)
  File "/opt/airflow/dags/xetra_etl.py", line 77, in run_etl
    date_to_process, previous_date = return_required_dates(META_FILE_PATH, src_date_format, INITIAL_DATE, today)
  File "/opt/airflow/dags/xetra_etl.py", line 9, in return_required_dates
    df_meta_file = pd.read_csv(meta_file_path)
NameError: name 'pd' is not defined
[2022-11-01 18:50:09,408] {taskinstance.py:1400} INFO - Marking task as FAILED. dag_id=xetra_DAG, task_id=run_xetra_etl, execution_date=20221101T184836, start_date=20221101T185008, end_date=20221101T185009
[2022-11-01 18:50:09,440] {standard_task_runner.py:97} ERROR - Failed to execute job 4 for task run_xetra_etl (name 'pd' is not defined; 4946)
[2022-11-01 18:50:09,461] {local_task_job.py:156} INFO - Task exited with return code 1
[2022-11-01 18:50:09,548] {local_task_job.py:273} INFO - 0 downstream tasks scheduled from follow-on schedule check
