[2022-12-11 13:30:23,711] {processor.py:153} INFO - Started process (PID=100) to work on /home/airflow/.local/lib/python3.7/site-packages/airflow/example_dags/example_local_kubernetes_executor.py
[2022-12-11 13:30:23,790] {processor.py:641} INFO - Processing file /home/airflow/.local/lib/python3.7/site-packages/airflow/example_dags/example_local_kubernetes_executor.py for tasks to queue
[2022-12-11 13:30:23,854] {logging_mixin.py:115} INFO - [2022-12-11 13:30:23,854] {dagbag.py:507} INFO - Filling up the DagBag from /home/airflow/.local/lib/python3.7/site-packages/airflow/example_dags/example_local_kubernetes_executor.py
[2022-12-11 13:30:24,101] {processor.py:651} INFO - DAG(s) dict_keys(['example_local_kubernetes_executor']) retrieved from /home/airflow/.local/lib/python3.7/site-packages/airflow/example_dags/example_local_kubernetes_executor.py
[2022-12-11 13:30:24,406] {logging_mixin.py:115} INFO - [2022-12-11 13:30:24,404] {dag.py:2371} INFO - Sync 1 DAGs
[2022-12-11 13:30:24,810] {logging_mixin.py:115} INFO - [2022-12-11 13:30:24,810] {dag.py:2919} INFO - Setting next_dagrun for example_local_kubernetes_executor to None, run_after=None
[2022-12-11 13:30:25,001] {processor.py:161} INFO - Processing /home/airflow/.local/lib/python3.7/site-packages/airflow/example_dags/example_local_kubernetes_executor.py took 1.355 seconds
[2022-12-11 13:30:59,711] {processor.py:153} INFO - Started process (PID=154) to work on /home/airflow/.local/lib/python3.7/site-packages/airflow/example_dags/example_local_kubernetes_executor.py
[2022-12-11 13:30:59,732] {processor.py:641} INFO - Processing file /home/airflow/.local/lib/python3.7/site-packages/airflow/example_dags/example_local_kubernetes_executor.py for tasks to queue
[2022-12-11 13:30:59,740] {logging_mixin.py:115} INFO - [2022-12-11 13:30:59,739] {dagbag.py:507} INFO - Filling up the DagBag from /home/airflow/.local/lib/python3.7/site-packages/airflow/example_dags/example_local_kubernetes_executor.py
[2022-12-11 13:31:00,011] {processor.py:651} INFO - DAG(s) dict_keys(['example_local_kubernetes_executor']) retrieved from /home/airflow/.local/lib/python3.7/site-packages/airflow/example_dags/example_local_kubernetes_executor.py
[2022-12-11 13:31:00,427] {logging_mixin.py:115} INFO - [2022-12-11 13:31:00,427] {dag.py:2371} INFO - Sync 1 DAGs
[2022-12-11 13:31:00,627] {logging_mixin.py:115} INFO - [2022-12-11 13:31:00,627] {dag.py:2919} INFO - Setting next_dagrun for example_local_kubernetes_executor to None, run_after=None
[2022-12-11 13:31:00,794] {processor.py:161} INFO - Processing /home/airflow/.local/lib/python3.7/site-packages/airflow/example_dags/example_local_kubernetes_executor.py took 1.144 seconds
[2022-12-11 13:31:52,848] {processor.py:153} INFO - Started process (PID=218) to work on /home/airflow/.local/lib/python3.7/site-packages/airflow/example_dags/example_local_kubernetes_executor.py
[2022-12-11 13:31:52,854] {processor.py:641} INFO - Processing file /home/airflow/.local/lib/python3.7/site-packages/airflow/example_dags/example_local_kubernetes_executor.py for tasks to queue
[2022-12-11 13:31:52,865] {logging_mixin.py:115} INFO - [2022-12-11 13:31:52,865] {dagbag.py:507} INFO - Filling up the DagBag from /home/airflow/.local/lib/python3.7/site-packages/airflow/example_dags/example_local_kubernetes_executor.py
[2022-12-11 13:31:53,334] {processor.py:651} INFO - DAG(s) dict_keys(['example_local_kubernetes_executor']) retrieved from /home/airflow/.local/lib/python3.7/site-packages/airflow/example_dags/example_local_kubernetes_executor.py
[2022-12-11 13:31:54,879] {processor.py:164} ERROR - Got an exception! Propagating...
Traceback (most recent call last):
  File "/home/airflow/.local/lib/python3.7/site-packages/sqlalchemy/engine/base.py", line 3141, in _wrap_pool_connect
    return fn()
  File "/home/airflow/.local/lib/python3.7/site-packages/sqlalchemy/pool/base.py", line 301, in connect
    return _ConnectionFairy._checkout(self)
  File "/home/airflow/.local/lib/python3.7/site-packages/sqlalchemy/pool/base.py", line 755, in _checkout
    fairy = _ConnectionRecord.checkout(pool)
  File "/home/airflow/.local/lib/python3.7/site-packages/sqlalchemy/pool/base.py", line 419, in checkout
    rec = pool._do_get()
  File "/home/airflow/.local/lib/python3.7/site-packages/sqlalchemy/pool/impl.py", line 145, in _do_get
    self._dec_overflow()
  File "/home/airflow/.local/lib/python3.7/site-packages/sqlalchemy/util/langhelpers.py", line 72, in __exit__
    with_traceback=exc_tb,
  File "/home/airflow/.local/lib/python3.7/site-packages/sqlalchemy/util/compat.py", line 211, in raise_
    raise exception
  File "/home/airflow/.local/lib/python3.7/site-packages/sqlalchemy/pool/impl.py", line 142, in _do_get
    return self._create_connection()
  File "/home/airflow/.local/lib/python3.7/site-packages/sqlalchemy/pool/base.py", line 247, in _create_connection
    return _ConnectionRecord(self)
  File "/home/airflow/.local/lib/python3.7/site-packages/sqlalchemy/pool/base.py", line 362, in __init__
    self.__connect(first_connect_check=True)
  File "/home/airflow/.local/lib/python3.7/site-packages/sqlalchemy/pool/base.py", line 605, in __connect
    pool.logger.debug("Error on connect(): %s", e)
  File "/home/airflow/.local/lib/python3.7/site-packages/sqlalchemy/util/langhelpers.py", line 72, in __exit__
    with_traceback=exc_tb,
  File "/home/airflow/.local/lib/python3.7/site-packages/sqlalchemy/util/compat.py", line 211, in raise_
    raise exception
  File "/home/airflow/.local/lib/python3.7/site-packages/sqlalchemy/pool/base.py", line 599, in __connect
    connection = pool._invoke_creator(self)
  File "/home/airflow/.local/lib/python3.7/site-packages/sqlalchemy/engine/create.py", line 578, in connect
    return dialect.connect(*cargs, **cparams)
  File "/home/airflow/.local/lib/python3.7/site-packages/sqlalchemy/engine/default.py", line 583, in connect
    return self.dbapi.connect(*cargs, **cparams)
  File "/home/airflow/.local/lib/python3.7/site-packages/psycopg2/__init__.py", line 122, in connect
    conn = _connect(dsn, connection_factory=connection_factory, **kwasync)
psycopg2.OperationalError: connection to server at "postgres" (172.18.0.3), port 5432 failed: FATAL:  the database system is shutting down


The above exception was the direct cause of the following exception:

Traceback (most recent call last):
  File "/home/airflow/.local/lib/python3.7/site-packages/airflow/dag_processing/processor.py", line 158, in _run_file_processor
    callback_requests=callback_requests,
  File "/home/airflow/.local/lib/python3.7/site-packages/airflow/utils/session.py", line 71, in wrapper
    return func(*args, session=session, **kwargs)
  File "/home/airflow/.local/lib/python3.7/site-packages/airflow/dag_processing/processor.py", line 660, in process_file
    dagbag.sync_to_db()
  File "/home/airflow/.local/lib/python3.7/site-packages/airflow/utils/session.py", line 71, in wrapper
    return func(*args, session=session, **kwargs)
  File "/home/airflow/.local/lib/python3.7/site-packages/airflow/models/dagbag.py", line 615, in sync_to_db
    for attempt in run_with_db_retries(logger=self.log):
  File "/home/airflow/.local/lib/python3.7/site-packages/tenacity/__init__.py", line 382, in __iter__
    do = self.iter(retry_state=retry_state)
  File "/home/airflow/.local/lib/python3.7/site-packages/tenacity/__init__.py", line 360, in iter
    raise retry_exc.reraise()
  File "/home/airflow/.local/lib/python3.7/site-packages/tenacity/__init__.py", line 193, in reraise
    raise self.last_attempt.result()
  File "/usr/local/lib/python3.7/concurrent/futures/_base.py", line 428, in result
    return self.__get_result()
  File "/usr/local/lib/python3.7/concurrent/futures/_base.py", line 384, in __get_result
    raise self._exception
  File "/home/airflow/.local/lib/python3.7/site-packages/airflow/models/dagbag.py", line 627, in sync_to_db
    serialize_errors.extend(_serialize_dag_capturing_errors(dag, session))
  File "/home/airflow/.local/lib/python3.7/site-packages/airflow/models/dagbag.py", line 601, in _serialize_dag_capturing_errors
    session=session,
  File "/home/airflow/.local/lib/python3.7/site-packages/airflow/utils/session.py", line 68, in wrapper
    return func(*args, **kwargs)
  File "/home/airflow/.local/lib/python3.7/site-packages/airflow/models/serialized_dag.py", line 142, in write_dag
    (timezone.utcnow() - timedelta(seconds=min_update_interval)) < cls.last_updated,
  File "/home/airflow/.local/lib/python3.7/site-packages/sqlalchemy/orm/query.py", line 2734, in first
    return self.limit(1)._iter().first()
  File "/home/airflow/.local/lib/python3.7/site-packages/sqlalchemy/orm/query.py", line 2821, in _iter
    execution_options={"_sa_orm_load_options": self.load_options},
  File "/home/airflow/.local/lib/python3.7/site-packages/sqlalchemy/orm/session.py", line 1669, in execute
    conn = self._connection_for_bind(bind, close_with_result=True)
  File "/home/airflow/.local/lib/python3.7/site-packages/sqlalchemy/orm/session.py", line 1520, in _connection_for_bind
    engine, execution_options
  File "/home/airflow/.local/lib/python3.7/site-packages/sqlalchemy/orm/session.py", line 747, in _connection_for_bind
    conn = bind.connect()
  File "/home/airflow/.local/lib/python3.7/site-packages/sqlalchemy/engine/base.py", line 3095, in connect
    return self._connection_cls(self, close_with_result=close_with_result)
  File "/home/airflow/.local/lib/python3.7/site-packages/sqlalchemy/engine/base.py", line 91, in __init__
    else engine.raw_connection()
  File "/home/airflow/.local/lib/python3.7/site-packages/sqlalchemy/engine/base.py", line 3174, in raw_connection
    return self._wrap_pool_connect(self.pool.connect, _connection)
  File "/home/airflow/.local/lib/python3.7/site-packages/sqlalchemy/engine/base.py", line 3145, in _wrap_pool_connect
    e, dialect, self
  File "/home/airflow/.local/lib/python3.7/site-packages/sqlalchemy/engine/base.py", line 2004, in _handle_dbapi_exception_noconnection
    sqlalchemy_exception, with_traceback=exc_info[2], from_=e
  File "/home/airflow/.local/lib/python3.7/site-packages/sqlalchemy/util/compat.py", line 211, in raise_
    raise exception
  File "/home/airflow/.local/lib/python3.7/site-packages/sqlalchemy/engine/base.py", line 3141, in _wrap_pool_connect
    return fn()
  File "/home/airflow/.local/lib/python3.7/site-packages/sqlalchemy/pool/base.py", line 301, in connect
    return _ConnectionFairy._checkout(self)
  File "/home/airflow/.local/lib/python3.7/site-packages/sqlalchemy/pool/base.py", line 755, in _checkout
    fairy = _ConnectionRecord.checkout(pool)
  File "/home/airflow/.local/lib/python3.7/site-packages/sqlalchemy/pool/base.py", line 419, in checkout
    rec = pool._do_get()
  File "/home/airflow/.local/lib/python3.7/site-packages/sqlalchemy/pool/impl.py", line 145, in _do_get
    self._dec_overflow()
  File "/home/airflow/.local/lib/python3.7/site-packages/sqlalchemy/util/langhelpers.py", line 72, in __exit__
    with_traceback=exc_tb,
  File "/home/airflow/.local/lib/python3.7/site-packages/sqlalchemy/util/compat.py", line 211, in raise_
    raise exception
  File "/home/airflow/.local/lib/python3.7/site-packages/sqlalchemy/pool/impl.py", line 142, in _do_get
    return self._create_connection()
  File "/home/airflow/.local/lib/python3.7/site-packages/sqlalchemy/pool/base.py", line 247, in _create_connection
    return _ConnectionRecord(self)
  File "/home/airflow/.local/lib/python3.7/site-packages/sqlalchemy/pool/base.py", line 362, in __init__
    self.__connect(first_connect_check=True)
  File "/home/airflow/.local/lib/python3.7/site-packages/sqlalchemy/pool/base.py", line 605, in __connect
    pool.logger.debug("Error on connect(): %s", e)
  File "/home/airflow/.local/lib/python3.7/site-packages/sqlalchemy/util/langhelpers.py", line 72, in __exit__
    with_traceback=exc_tb,
  File "/home/airflow/.local/lib/python3.7/site-packages/sqlalchemy/util/compat.py", line 211, in raise_
    raise exception
  File "/home/airflow/.local/lib/python3.7/site-packages/sqlalchemy/pool/base.py", line 599, in __connect
    connection = pool._invoke_creator(self)
  File "/home/airflow/.local/lib/python3.7/site-packages/sqlalchemy/engine/create.py", line 578, in connect
    return dialect.connect(*cargs, **cparams)
  File "/home/airflow/.local/lib/python3.7/site-packages/sqlalchemy/engine/default.py", line 583, in connect
    return self.dbapi.connect(*cargs, **cparams)
  File "/home/airflow/.local/lib/python3.7/site-packages/psycopg2/__init__.py", line 122, in connect
    conn = _connect(dsn, connection_factory=connection_factory, **kwasync)
sqlalchemy.exc.OperationalError: (psycopg2.OperationalError) connection to server at "postgres" (172.18.0.3), port 5432 failed: FATAL:  the database system is shutting down

(Background on this error at: http://sqlalche.me/e/14/e3q8)
